<?xml version="1.0"?>
<robot name="spark" xmlns:xacro="http://www.ros.org/wiki/xacro">

  <xacro:include filename="$(find spark_description)/urdf/materials.xacro" />

  <xacro:include filename="$(find spark_gazebo)/gazebo/materials.gazebo" />
  <xacro:include filename="$(find spark_gazebo)/gazebo/physics.gazebo" />
  <xacro:include filename="$(find spark_gazebo)/gazebo/plugins.gazebo" />


  <link name="base_link">
    <inertial>
      <origin xyz="-1.8999995568076314e-16 -1.519999645446105e-16 0.06640496427214614" rpy="0 0 0" />
      <mass value="1.0148048513223018" />
      <inertia ixx="0.019433" iyy="0.01845" izz="0.034221" ixy="0.0" iyz="-0.0" ixz="-0.0" />
    </inertial>
    <visual>
      <origin xyz="0 0 0" rpy="0 0 0" />
      <geometry>
        <mesh filename="file://$(find spark_description)/meshes/base_link.stl"
          scale="0.001 0.001 0.001" />
        <!-- <mesh filename="file://$(find spark_description)/meshes/base_link.stl"
          scale="0.001 0.001 0.0005" /> -->
      </geometry>
      <material name="cyan" />
    </visual>
    <collision>
      <origin xyz="0 0 0" rpy="0 0 0" />
      <geometry>
        <mesh filename="file://$(find spark_description)/meshes/base_link.stl"
          scale="0.001 0.001 0.001" />
        <!-- <mesh filename="file://$(find spark_description)/meshes/base_link.stl"
          scale="0.001 0.001 0.0005" /> -->
      </geometry>
    </collision>
  </link>


  <link name="left_wheel">
    <inertial>
      <origin xyz="4.777250796293949e-17 0.004523461298064829 6.938893903907228e-18" rpy="0 0 0" />
      <mass value="0.08590144455112657" />
      <inertia ixx="5.4e-05" iyy="8.9e-05" izz="5.4e-05" ixy="0.0" iyz="0.0" ixz="-0.0" />
    </inertial>
    <visual>
      <origin xyz="-0.0 -0.15 -0.04" rpy="0 0 0" />
      <geometry>
        <mesh filename="file://$(find spark_description)/meshes/left_wheel.stl"
          scale="0.001 0.001 0.001" />
      </geometry>
      <material name="black" />
    </visual>
    <collision>
      <origin xyz="-0.0 -0.15 -0.04" rpy="0 0 0" />
      <geometry>
        <mesh filename="file://$(find spark_description)/meshes/left_wheel.stl"
          scale="0.001 0.001 0.001" />
      </geometry>
    </collision>
  </link>

  <link name="right_wheel">
    <inertial>
      <origin xyz="1.0074933496468999e-16 -0.004523461298064718 6.938893903907228e-18" rpy="0 0 0" />
      <mass value="0.08590144455112657" />
      <inertia ixx="5.4e-05" iyy="8.9e-05" izz="5.4e-05" ixy="-0.0" iyz="0.0" ixz="0.0" />
    </inertial>
    <visual>
      <origin xyz="-0.0 0.15 -0.04" rpy="0 0 0" />
      <geometry>
        <mesh filename="file://$(find spark_description)/meshes/right_wheel.stl"
          scale="0.001 0.001 0.001" />
      </geometry>
      <material name="black" />
    </visual>
    <collision>
      <origin xyz="-0.0 0.15 -0.04" rpy="0 0 0" />
      <geometry>
        <mesh filename="file://$(find spark_description)/meshes/right_wheel.stl"
          scale="0.001 0.001 0.001" />
      </geometry>
    </collision>
  </link>

  <link name="bl_caster">
    <inertial>
      <origin xyz="0.01499999999951665 0.015000000000000041 -0.022526171875000035" rpy="0 0 0" />
      <mass value="0.002333836822474266" />
      <inertia ixx="0.0" iyy="0.0" izz="0.0" ixy="0.0" iyz="-0.0" ixz="0.0" />
    </inertial>
    <visual>
      <origin xyz="0.155 0.155 -0.01575" rpy="0 0 0" />
      <geometry>
        <mesh filename="file://$(find spark_description)/meshes/bl_caster.stl"
          scale="0.001 0.001 0.001" />
      </geometry>
      <material name="white" />
    </visual>
    <collision>
      <origin xyz="0.175 0.175 -0.01575" rpy="0 0 0" />
      <geometry>
        <mesh filename="file://$(find spark_description)/meshes/bl_caster.stl"
          scale="0.001 0.001 0.001" />> </geometry>
    </collision>
  </link>

  <link name="br_caster">
    <inertial>
      <origin xyz="0.01499999999951665 0.015000000000000041 -0.022526171875000035" rpy="0 0 0" />
      <mass value="0.002333836822474266" />
      <inertia ixx="0.0" iyy="0.0" izz="0.0" ixy="0.0" iyz="-0.0" ixz="0.0" />
    </inertial>
    <visual>
      <origin xyz="0.155 0.155 -0.01575" rpy="0 0 0" />
      <geometry>
        <mesh filename="file://$(find spark_description)/meshes/br_caster.stl"
          scale="0.001 0.001 0.001" />
      </geometry>
      <material name="white" />
    </visual>
    <collision>
      <origin xyz="0.175 0.175 -0.01575" rpy="0 0 0" />
      <geometry>
        <mesh filename="file://$(find spark_description)/meshes/br_caster.stl"
          scale="0.001 0.001 0.001" />> </geometry>
    </collision>
  </link>

  <link name="fr_caster">
    <inertial>
      <origin xyz="0.01499999999951665 0.015000000000000041 -0.022526171875000035" rpy="0 0 0" />
      <mass value="0.002333836822474266" />
      <inertia ixx="0.0" iyy="0.0" izz="0.0" ixy="0.0" iyz="-0.0" ixz="0.0" />
    </inertial>
    <visual>
      <origin xyz="0.155 0.155 -0.01575" rpy="0 0 0" />
      <geometry>
        <mesh filename="file://$(find spark_description)/meshes/fr_caster.stl"
          scale="0.001 0.001 0.001" />
      </geometry>
      <material name="white" />
    </visual>
    <collision>
      <origin xyz="0.175 0.175 -0.01575" rpy="0 0 0" />
      <geometry>
        <mesh filename="file://$(find spark_description)/meshes/fr_caster.stl"
          scale="0.001 0.001 0.001" />> </geometry>
    </collision>
  </link>

  <link name="fl_caster">
    <inertial>
      <origin xyz="0.01499999999951665 0.015000000000000041 -0.022526171875000035" rpy="0 0 0" />
      <mass value="0.002333836822474266" />
      <inertia ixx="0.0" iyy="0.0" izz="0.0" ixy="0.0" iyz="-0.0" ixz="0.0" />
    </inertial>
    <visual>
      <origin xyz="0.155 0.155 -0.01575" rpy="0 0 0" />
      <geometry>
        <mesh filename="file://$(find spark_description)/meshes/fl_caster.stl"
          scale="0.001 0.001 0.001" />
      </geometry>
      <material name="white" />
    </visual>
    <collision>
      <origin xyz="0.175 0.175 -0.01575" rpy="0 0 0" />
      <geometry>
        <mesh filename="file://$(find spark_description)/meshes/fl_caster.stl"
          scale="0.001 0.001 0.001" />> </geometry>
    </collision>
  </link>

  <link name="front_lidar_base">
    <inertial>
      <origin xyz="0.0 0.0 0.0" rpy="0 0 0" />
      <mass value="0.0969073180413002" />
      <inertia ixx="2.8e-05" iyy="5.6e-05" izz="6.5e-05" ixy="0.0" iyz="0.0" ixz="9e-06" />
    </inertial>
    <visual>
      <origin xyz="0.067 0.0 -0.148" rpy="0 0 0" />
      <geometry>
        <mesh filename="file://$(find spark_description)/meshes/front_lidar_base.stl"
          scale="0.001 0.001 0.001" />
      </geometry>
      <material name="orange" />
    </visual>
    <collision>
      <origin xyz="0.067 0.0 -0.148" rpy="0 0 0" />
      <geometry>
        <mesh filename="file://$(find spark_description)/meshes/front_lidar_base.stl"
          scale="0.001 0.001 0.001" />
      </geometry>
    </collision>
  </link>

  <link name="rear_lidar_base">
    <inertial>
      <origin xyz="0.0 0.0 0.0" rpy="0 0 0" />
      <mass value="0.0969073180413002" />
      <inertia ixx="2.8e-05" iyy="5.6e-05" izz="6.5e-05" ixy="0.0" iyz="0.0" ixz="9e-06" />
    </inertial>
    <visual>
      <origin xyz="0.067 0.0 -0.148" rpy="0 0 0" />
      <geometry>
        <mesh filename="file://$(find spark_description)/meshes/rear_lidar_base.stl"
          scale="0.001 0.001 0.001" />
      </geometry>
      <material name="orange" />
    </visual>
    <collision>
      <origin xyz="0.067 0.0 -0.148" rpy="0 0 0" />
      <geometry>
        <mesh filename="file://$(find spark_description)/meshes/rear_lidar_base.stl"
          scale="0.001 0.001 0.001" />
      </geometry>
    </collision>
  </link>

  <link name="front_lidar_sensor">
  </link>

  <link name="rear_lidar_sensor">
  </link>

  <link name="merge_lidar">
  </link>

  <link name="imu_link">
    <inertial>
      <origin rpy="0 0 0" xyz="-0.005006317892412869 0.010331821776814253 0.0005641458401822869" />
      <mass value="0.0005786974233911084" />
      <inertia ixx="0.0" ixy="0.0" ixz="-0.0" iyy="0.0" iyz="-0.0" izz="0.0" />
    </inertial>
    <visual>
      <origin rpy="0 0 0" xyz="-0.04 0.01025 -0.10543" />
      <geometry>
        <mesh filename="file://$(find spark_description)/meshes/imu.stl" scale="0.001 0.001 0.001" />
      </geometry>
      <material name="white" />
    </visual>
    <collision>
      <origin rpy="0 0 0" xyz="-0.04 0.01025 -0.10543" />
      <geometry>
        <mesh filename="file://$(find spark_description)/meshes/imu.stl" scale="0.001 0.001 0.001" />
      </geometry>
    </collision>
  </link>


  <joint name="left_wheel_joint" type="continuous">
    <origin xyz="0.0 0.15 0.04" rpy="0 0 0" />
    <parent link="base_link" />
    <child link="left_wheel" />
    <axis xyz="0.0 1.0 0.0" />
  </joint>

  <joint name="right_wheel_joint" type="continuous">
    <origin xyz="0.0 -0.15 0.04" rpy="0 0 0" />
    <parent link="base_link" />
    <child link="right_wheel" />
    <axis xyz="0.0 1.0 0.0" />
  </joint>

  <joint name="base_link_bl_caster" type="fixed">
    <origin xyz="-0.17 0.17 0.01575" rpy="0 0 0" />
    <parent link="base_link" />
    <child link="bl_caster" />
  </joint>

  <joint name="base_link_br_caster" type="fixed">
    <origin xyz="-0.17 -0.17 0.01575" rpy="0 0 0" />
    <parent link="base_link" />
    <child link="br_caster" />
  </joint>

  <joint name="base_link_fl_caster" type="fixed">
    <origin xyz="0.17 0.17 0.01575" rpy="0 0 0" />
    <parent link="base_link" />
    <child link="fl_caster" />
  </joint>

  <joint name="base_link_fr_caster" type="fixed">
    <origin xyz="0.17 -0.17 0.01575" rpy="0 0 0" />
    <parent link="base_link" />
    <child link="fr_caster" />
  </joint>

  <joint name="front_scan_base" type="fixed">
    <parent link="base_link" />
    <child link="front_lidar_base" />
    <origin xyz="0.115 0 0.116" rpy="0 0 0" />
  </joint>

  <joint name="rear_scan_base" type="fixed">
    <parent link="base_link" />
    <child link="rear_lidar_base" />
    <origin xyz="-0.185 0 0.116" rpy="0 0 0" />
  </joint>

  <joint name="front_lidar_sensor_joint" type="fixed">
    <parent link="front_lidar_base" />
    <child link="front_lidar_sensor" />
    <origin xyz="0.035 0 0.045" rpy="0 0 0" />
    <!-- <origin xyz="0.035 0 -0.035" rpy="0 0 0" /> -->
  </joint>

  <joint name="rear_lidar_sensor_joint" type="fixed">
    <parent link="rear_lidar_base" />
    <child link="rear_lidar_sensor" />
    <origin xyz="0.035 0 0.045" rpy="0 0 0" />
    <!-- <origin xyz="0.035 0 -0.035" rpy="0 0 0" /> -->
  </joint>

  <joint name="merger_lidar_joint" type="fixed">
    <parent link="base_link" />
    <child link="merge_lidar" />
    <origin xyz="0.0 0.0 0.161" rpy="0 0 0" />
    <!-- <origin xyz="0.0 0.0 0.051" rpy="0 0 0" /> -->
  </joint>

  <joint name="imu_joint" type="fixed">
    <parent link="base_link" />
    <child link="imu_link" />
    <origin xyz="0.0 0.0 0.05" rpy="0 0 0" />
  </joint>

  <!-- ################################## ARM ################################## -->


  <!-- import main macro -->
  <xacro:include filename="$(find spark_description)/urdf/inc/ur_macro.xacro" />

  <!-- parameters -->

  <xacro:arg name="joint_limit_params"
    default="$(find spark_description)/config/ur3/joint_limits.yaml" />
  <xacro:arg name="kinematics_params"
    default="$(find spark_description)/config/ur3/default_kinematics.yaml" />
  <xacro:arg name="physical_params"
    default="$(find spark_description)/config/ur3/physical_parameters.yaml" />
  <xacro:arg name="visual_params"
    default="$(find spark_description)/config/ur3/visual_parameters.yaml" />

  <!-- legal values:
           - hardware_interface/PositionJointInterface
           - hardware_interface/VelocityJointInterface
           - hardware_interface/EffortJointInterface
     -->

  <!--common
  parameters -->
  <xacro:arg name="transmission_hw_interface" default="hardware_interface/PositionJointInterface" />
  <xacro:arg name="safety_limits" default="false" />
  <xacro:arg name="safety_pos_margin" default="0.15" />
  <xacro:arg name="safety_k_position" default="20" />

  <!-- arm -->

  <xacro:ur_robot
    prefix=""
    joint_limits_parameters_file="$(arg joint_limit_params)"
    kinematics_parameters_file="$(arg kinematics_params)"
    physical_parameters_file="$(arg physical_params)"
    visual_parameters_file="$(arg visual_params)"
    transmission_hw_interface="$(arg transmission_hw_interface)"
    safety_limits="$(arg safety_limits)"
    safety_pos_margin="$(arg safety_pos_margin)"
    safety_k_position="$(arg safety_k_position)" />


  <joint name="amr_to_robot" type="fixed">
    <parent link="base_link" />
    <child link="ur_base_link" />
    <origin xyz="0.0 0.0 0.115" rpy="0 0 0" />
  </joint>

  <link name="tool0_controller" />
  <joint name="tool_controller_fake_joint" type="fixed">
    <parent link="tool0" />
    <child link="tool0_controller" />
    <origin xyz="0 0 0" rpy="0 0 0" />
  </joint>

</robot>